<?xml version="1.0" encoding="UTF-8"?>
<testng-results ignored="0" total="2" passed="0" failed="2" skipped="0">
  <reporter-output>
  </reporter-output>
  <suite started-at="2020-02-18T19:59:45 IST" name="mobile-automation-framework" finished-at="2020-02-18T20:01:24 IST" duration-ms="99341">
    <groups>
      <group name="cucumber">
        <method signature="CucumberRunnerUtil.feature(cucumber.api.testng.CucumberFeatureWrapper)[pri:0, instance:runner.CucumberRunnerUtil@78aab498]" name="feature" class="runner.CucumberRunnerUtil"/>
      </group> <!-- cucumber -->
    </groups>
    <test started-at="2020-02-18T19:59:45 IST" name="automation-tests" finished-at="2020-02-18T20:01:24 IST" duration-ms="99341">
      <class name="runner.CucumberRunnerUtil">
        <test-method is-config="true" signature="setCreateSession()[pri:0, instance:runner.CucumberRunnerUtil@78aab498]" started-at="2020-02-18T19:59:45 IST" name="setCreateSession" finished-at="2020-02-18T19:59:45 IST" duration-ms="9" status="PASS">
          <reporter-output>
          </reporter-output>
        </test-method> <!-- setCreateSession -->
        <test-method is-config="true" signature="setUpClass()[pri:0, instance:runner.CucumberRunnerUtil@78aab498]" started-at="2020-02-18T19:59:45 IST" name="setUpClass" finished-at="2020-02-18T19:59:46 IST" duration-ms="1539" status="PASS">
          <reporter-output>
          </reporter-output>
        </test-method> <!-- setUpClass -->
        <test-method signature="feature(cucumber.api.testng.CucumberFeatureWrapper)[pri:0, instance:runner.CucumberRunnerUtil@78aab498]" started-at="2020-02-18T19:59:47 IST" name="feature" description="Runs Cucumber Feature" data-provider="features" finished-at="2020-02-18T20:00:43 IST" duration-ms="56945" status="FAIL">
          <params>
            <param index="0">
              <value>
                <![CDATA[Validate Different Options]]>
              </value>
            </param>
          </params>
          <exception class="cucumber.runtime.CucumberException">
            <message>
              <![CDATA[java.lang.AssertionError: Login Sucessfull did not expect to find [true] but found [false]]]>
            </message>
            <full-stacktrace>
              <![CDATA[cucumber.runtime.CucumberException: java.lang.AssertionError: Login Sucessfull did not expect to find [true] but found [false]
at cucumber.api.testng.TestNGCucumberRunner.runCucumber(TestNGCucumberRunner.java:69)
at runner.CucumberRunnerUtil.feature(CucumberRunnerUtil.java:84)
at java.base/jdk.internal.reflect.NativeMethodAccessorImpl.invoke0(Native Method)
at java.base/jdk.internal.reflect.NativeMethodAccessorImpl.invoke(NativeMethodAccessorImpl.java:62)
at java.base/jdk.internal.reflect.DelegatingMethodAccessorImpl.invoke(DelegatingMethodAccessorImpl.java:43)
at java.base/java.lang.reflect.Method.invoke(Method.java:567)
at org.testng.internal.MethodInvocationHelper.invokeMethod(MethodInvocationHelper.java:133)
at org.testng.internal.TestInvoker.invokeMethod(TestInvoker.java:584)
at org.testng.internal.TestInvoker.invokeTestMethod(TestInvoker.java:172)
at org.testng.internal.MethodRunner.runInSequence(MethodRunner.java:46)
at org.testng.internal.TestInvoker$MethodInvocationAgent.invoke(TestInvoker.java:804)
at org.testng.internal.TestInvoker.invokeTestMethods(TestInvoker.java:145)
at org.testng.internal.TestMethodWorker.invokeTestMethods(TestMethodWorker.java:146)
at org.testng.internal.TestMethodWorker.run(TestMethodWorker.java:128)
at java.base/java.util.ArrayList.forEach(ArrayList.java:1540)
at org.testng.TestRunner.privateRun(TestRunner.java:770)
at org.testng.TestRunner.run(TestRunner.java:591)
at org.testng.SuiteRunner.runTest(SuiteRunner.java:402)
at org.testng.SuiteRunner.runSequentially(SuiteRunner.java:396)
at org.testng.SuiteRunner.privateRun(SuiteRunner.java:355)
at org.testng.SuiteRunner.run(SuiteRunner.java:304)
at org.testng.SuiteRunnerWorker.runSuite(SuiteRunnerWorker.java:53)
at org.testng.SuiteRunnerWorker.run(SuiteRunnerWorker.java:96)
at org.testng.TestNG.runSuitesSequentially(TestNG.java:1180)
at org.testng.TestNG.runSuitesLocally(TestNG.java:1102)
at org.testng.TestNG.runSuites(TestNG.java:1032)
at org.testng.TestNG.run(TestNG.java:1000)
at org.testng.remote.AbstractRemoteTestNG.run(AbstractRemoteTestNG.java:115)
at org.testng.remote.RemoteTestNG.initAndRun(RemoteTestNG.java:251)
at org.testng.remote.RemoteTestNG.main(RemoteTestNG.java:77)
Caused by: java.lang.AssertionError: Login Sucessfull did not expect to find [true] but found [false]
at org.testng.Assert.fail(Assert.java:97)
at org.testng.Assert.failNotEquals(Assert.java:969)
at org.testng.Assert.assertTrue(Assert.java:43)
at page.actions.loginPage.loginToSFDCapp(loginPage.java:36)
at steps.AppiumScenario.i_open_the_application(AppiumScenario.java:16)
at ✽.Given "TMUser" logs into the application(Appium.feature:8)
]]>
            </full-stacktrace>
          </exception> <!-- cucumber.runtime.CucumberException -->
          <reporter-output>
          </reporter-output>
        </test-method> <!-- feature -->
        <test-method signature="feature(cucumber.api.testng.CucumberFeatureWrapper)[pri:0, instance:runner.CucumberRunnerUtil@78aab498]" started-at="2020-02-18T20:00:43 IST" name="feature" description="Runs Cucumber Feature" data-provider="features" finished-at="2020-02-18T20:01:24 IST" duration-ms="40758" status="FAIL">
          <params>
            <param index="0">
              <value>
                <![CDATA[Validate second feature]]>
              </value>
            </param>
          </params>
          <exception class="cucumber.runtime.CucumberException">
            <message>
              <![CDATA[java.lang.AssertionError: Login Sucessfull did not expect to find [true] but found [false]]]>
            </message>
            <full-stacktrace>
              <![CDATA[cucumber.runtime.CucumberException: java.lang.AssertionError: Login Sucessfull did not expect to find [true] but found [false]
at cucumber.api.testng.TestNGCucumberRunner.runCucumber(TestNGCucumberRunner.java:69)
at runner.CucumberRunnerUtil.feature(CucumberRunnerUtil.java:84)
at java.base/jdk.internal.reflect.NativeMethodAccessorImpl.invoke0(Native Method)
at java.base/jdk.internal.reflect.NativeMethodAccessorImpl.invoke(NativeMethodAccessorImpl.java:62)
at java.base/jdk.internal.reflect.DelegatingMethodAccessorImpl.invoke(DelegatingMethodAccessorImpl.java:43)
at java.base/java.lang.reflect.Method.invoke(Method.java:567)
at org.testng.internal.MethodInvocationHelper.invokeMethod(MethodInvocationHelper.java:133)
at org.testng.internal.TestInvoker.invokeMethod(TestInvoker.java:584)
at org.testng.internal.TestInvoker.invokeTestMethod(TestInvoker.java:172)
at org.testng.internal.MethodRunner.runInSequence(MethodRunner.java:46)
at org.testng.internal.TestInvoker$MethodInvocationAgent.invoke(TestInvoker.java:804)
at org.testng.internal.TestInvoker.invokeTestMethods(TestInvoker.java:145)
at org.testng.internal.TestMethodWorker.invokeTestMethods(TestMethodWorker.java:146)
at org.testng.internal.TestMethodWorker.run(TestMethodWorker.java:128)
at java.base/java.util.ArrayList.forEach(ArrayList.java:1540)
at org.testng.TestRunner.privateRun(TestRunner.java:770)
at org.testng.TestRunner.run(TestRunner.java:591)
at org.testng.SuiteRunner.runTest(SuiteRunner.java:402)
at org.testng.SuiteRunner.runSequentially(SuiteRunner.java:396)
at org.testng.SuiteRunner.privateRun(SuiteRunner.java:355)
at org.testng.SuiteRunner.run(SuiteRunner.java:304)
at org.testng.SuiteRunnerWorker.runSuite(SuiteRunnerWorker.java:53)
at org.testng.SuiteRunnerWorker.run(SuiteRunnerWorker.java:96)
at org.testng.TestNG.runSuitesSequentially(TestNG.java:1180)
at org.testng.TestNG.runSuitesLocally(TestNG.java:1102)
at org.testng.TestNG.runSuites(TestNG.java:1032)
at org.testng.TestNG.run(TestNG.java:1000)
at org.testng.remote.AbstractRemoteTestNG.run(AbstractRemoteTestNG.java:115)
at org.testng.remote.RemoteTestNG.initAndRun(RemoteTestNG.java:251)
at org.testng.remote.RemoteTestNG.main(RemoteTestNG.java:77)
Caused by: java.lang.AssertionError: Login Sucessfull did not expect to find [true] but found [false]
at org.testng.Assert.fail(Assert.java:97)
at org.testng.Assert.failNotEquals(Assert.java:969)
at org.testng.Assert.assertTrue(Assert.java:43)
at page.actions.loginPage.loginToSFDCapp(loginPage.java:36)
at steps.AppiumScenario.i_open_the_application(AppiumScenario.java:16)
at ✽.Given "TMUser" logs into the application(secoundFeature.feature:7)
]]>
            </full-stacktrace>
          </exception> <!-- cucumber.runtime.CucumberException -->
          <reporter-output>
          </reporter-output>
        </test-method> <!-- feature -->
        <test-method is-config="true" signature="tearDownClass()[pri:0, instance:runner.CucumberRunnerUtil@78aab498]" started-at="2020-02-18T20:01:24 IST" name="tearDownClass" finished-at="2020-02-18T20:01:24 IST" duration-ms="27" status="PASS">
          <reporter-output>
          </reporter-output>
        </test-method> <!-- tearDownClass -->
        <test-method is-config="true" signature="setDestroySession()[pri:0, instance:runner.CucumberRunnerUtil@78aab498]" started-at="2020-02-18T20:01:26 IST" name="setDestroySession" finished-at="2020-02-18T20:01:26 IST" duration-ms="0" status="PASS">
          <reporter-output>
          </reporter-output>
        </test-method> <!-- setDestroySession -->
        <test-method is-config="true" signature="cleanUp()[pri:0, instance:runner.CucumberRunnerUtil@78aab498]" started-at="2020-02-18T20:01:26 IST" name="cleanUp" finished-at="2020-02-18T20:01:26 IST" duration-ms="0" status="PASS">
          <reporter-output>
          </reporter-output>
        </test-method> <!-- cleanUp -->
      </class> <!-- runner.CucumberRunnerUtil -->
    </test> <!-- automation-tests -->
  </suite> <!-- mobile-automation-framework -->
</testng-results>
